2020-04-10 21:31:29,718 ERROR: Exception on /edit_profile [POST] [in /mnt/c/Users/hp/Documents/flask_learning/microblog/venv/lib/python3.5/site-packages/flask/app.py:1891]
Traceback (most recent call last):
  File "/mnt/c/Users/hp/Documents/flask_learning/microblog/venv/lib/python3.5/site-packages/sqlalchemy/engine/base.py", line 1248, in _execute_context
    cursor, statement, parameters, context
  File "/mnt/c/Users/hp/Documents/flask_learning/microblog/venv/lib/python3.5/site-packages/sqlalchemy/engine/default.py", line 588, in do_execute
    cursor.execute(statement, parameters)
sqlite3.IntegrityError: UNIQUE constraint failed: user.username

The above exception was the direct cause of the following exception:

Traceback (most recent call last):
  File "/mnt/c/Users/hp/Documents/flask_learning/microblog/venv/lib/python3.5/site-packages/flask/app.py", line 2446, in wsgi_app
    response = self.full_dispatch_request()
  File "/mnt/c/Users/hp/Documents/flask_learning/microblog/venv/lib/python3.5/site-packages/flask/app.py", line 1951, in full_dispatch_request
    rv = self.handle_user_exception(e)
  File "/mnt/c/Users/hp/Documents/flask_learning/microblog/venv/lib/python3.5/site-packages/flask/app.py", line 1820, in handle_user_exception
    reraise(exc_type, exc_value, tb)
  File "/mnt/c/Users/hp/Documents/flask_learning/microblog/venv/lib/python3.5/site-packages/flask/_compat.py", line 39, in reraise
    raise value
  File "/mnt/c/Users/hp/Documents/flask_learning/microblog/venv/lib/python3.5/site-packages/flask/app.py", line 1949, in full_dispatch_request
    rv = self.dispatch_request()
  File "/mnt/c/Users/hp/Documents/flask_learning/microblog/venv/lib/python3.5/site-packages/flask/app.py", line 1935, in dispatch_request
    return self.view_functions[rule.endpoint](**req.view_args)
  File "/mnt/c/Users/hp/Documents/flask_learning/microblog/venv/lib/python3.5/site-packages/flask_login/utils.py", line 272, in decorated_view
    return func(*args, **kwargs)
  File "/mnt/c/Users/hp/Documents/flask_learning/microblog/app/routes.py", line 106, in edit_profile
    db.session.commit()
  File "/mnt/c/Users/hp/Documents/flask_learning/microblog/venv/lib/python3.5/site-packages/sqlalchemy/orm/scoping.py", line 162, in do
    return getattr(self.registry(), name)(*args, **kwargs)
  File "/mnt/c/Users/hp/Documents/flask_learning/microblog/venv/lib/python3.5/site-packages/sqlalchemy/orm/session.py", line 1036, in commit
    self.transaction.commit()
  File "/mnt/c/Users/hp/Documents/flask_learning/microblog/venv/lib/python3.5/site-packages/sqlalchemy/orm/session.py", line 503, in commit
    self._prepare_impl()
  File "/mnt/c/Users/hp/Documents/flask_learning/microblog/venv/lib/python3.5/site-packages/sqlalchemy/orm/session.py", line 482, in _prepare_impl
    self.session.flush()
  File "/mnt/c/Users/hp/Documents/flask_learning/microblog/venv/lib/python3.5/site-packages/sqlalchemy/orm/session.py", line 2496, in flush
    self._flush(objects)
  File "/mnt/c/Users/hp/Documents/flask_learning/microblog/venv/lib/python3.5/site-packages/sqlalchemy/orm/session.py", line 2637, in _flush
    transaction.rollback(_capture_exception=True)
  File "/mnt/c/Users/hp/Documents/flask_learning/microblog/venv/lib/python3.5/site-packages/sqlalchemy/util/langhelpers.py", line 69, in __exit__
    exc_value, with_traceback=exc_tb,
  File "/mnt/c/Users/hp/Documents/flask_learning/microblog/venv/lib/python3.5/site-packages/sqlalchemy/util/compat.py", line 178, in raise_
    raise exception
  File "/mnt/c/Users/hp/Documents/flask_learning/microblog/venv/lib/python3.5/site-packages/sqlalchemy/orm/session.py", line 2597, in _flush
    flush_context.execute()
  File "/mnt/c/Users/hp/Documents/flask_learning/microblog/venv/lib/python3.5/site-packages/sqlalchemy/orm/unitofwork.py", line 422, in execute
    rec.execute(self)
  File "/mnt/c/Users/hp/Documents/flask_learning/microblog/venv/lib/python3.5/site-packages/sqlalchemy/orm/unitofwork.py", line 589, in execute
    uow,
  File "/mnt/c/Users/hp/Documents/flask_learning/microblog/venv/lib/python3.5/site-packages/sqlalchemy/orm/persistence.py", line 236, in save_obj
    update,
  File "/mnt/c/Users/hp/Documents/flask_learning/microblog/venv/lib/python3.5/site-packages/sqlalchemy/orm/persistence.py", line 995, in _emit_update_statements
    statement, multiparams
  File "/mnt/c/Users/hp/Documents/flask_learning/microblog/venv/lib/python3.5/site-packages/sqlalchemy/engine/base.py", line 984, in execute
    return meth(self, multiparams, params)
  File "/mnt/c/Users/hp/Documents/flask_learning/microblog/venv/lib/python3.5/site-packages/sqlalchemy/sql/elements.py", line 293, in _execute_on_connection
    return connection._execute_clauseelement(self, multiparams, params)
  File "/mnt/c/Users/hp/Documents/flask_learning/microblog/venv/lib/python3.5/site-packages/sqlalchemy/engine/base.py", line 1103, in _execute_clauseelement
    distilled_params,
  File "/mnt/c/Users/hp/Documents/flask_learning/microblog/venv/lib/python3.5/site-packages/sqlalchemy/engine/base.py", line 1288, in _execute_context
    e, statement, parameters, cursor, context
  File "/mnt/c/Users/hp/Documents/flask_learning/microblog/venv/lib/python3.5/site-packages/sqlalchemy/engine/base.py", line 1482, in _handle_dbapi_exception
    sqlalchemy_exception, with_traceback=exc_info[2], from_=e
  File "/mnt/c/Users/hp/Documents/flask_learning/microblog/venv/lib/python3.5/site-packages/sqlalchemy/util/compat.py", line 178, in raise_
    raise exception
  File "/mnt/c/Users/hp/Documents/flask_learning/microblog/venv/lib/python3.5/site-packages/sqlalchemy/engine/base.py", line 1248, in _execute_context
    cursor, statement, parameters, context
  File "/mnt/c/Users/hp/Documents/flask_learning/microblog/venv/lib/python3.5/site-packages/sqlalchemy/engine/default.py", line 588, in do_execute
    cursor.execute(statement, parameters)
sqlalchemy.exc.IntegrityError: (sqlite3.IntegrityError) UNIQUE constraint failed: user.username
[SQL: UPDATE user SET username=?, about_me=? WHERE user.id = ?]
[parameters: ('Steve', 'Sandstorm.', 3)]
(Background on this error at: http://sqlalche.me/e/gkpj)
2020-04-11 09:08:37,029 INFO: My Blog startup. [in /mnt/c/Users/hp/Documents/flask_learning/microblog/app/__init__.py:49]
2020-04-11 09:09:14,331 INFO: My Blog startup. [in /mnt/c/Users/hp/Documents/flask_learning/microblog/app/__init__.py:49]
2020-04-11 09:10:26,189 INFO: My Blog startup. [in /mnt/c/Users/hp/Documents/flask_learning/microblog/app/__init__.py:49]
2020-04-11 09:10:46,307 INFO: My Blog startup. [in /mnt/c/Users/hp/Documents/flask_learning/microblog/app/__init__.py:49]
2020-04-11 09:11:27,767 INFO: My Blog startup. [in /mnt/c/Users/hp/Documents/flask_learning/microblog/app/__init__.py:49]
2020-04-11 16:09:02,212 INFO: My Blog startup. [in /mnt/c/Users/hp/Documents/flask_learning/microblog/app/__init__.py:49]
2020-04-11 16:09:20,642 ERROR: Exception on /user/Steve [GET] [in /mnt/c/Users/hp/Documents/flask_learning/microblog/venv/lib/python3.5/site-packages/flask/app.py:1891]
Traceback (most recent call last):
  File "/mnt/c/Users/hp/Documents/flask_learning/microblog/venv/lib/python3.5/site-packages/flask/app.py", line 2446, in wsgi_app
    response = self.full_dispatch_request()
  File "/mnt/c/Users/hp/Documents/flask_learning/microblog/venv/lib/python3.5/site-packages/flask/app.py", line 1951, in full_dispatch_request
    rv = self.handle_user_exception(e)
  File "/mnt/c/Users/hp/Documents/flask_learning/microblog/venv/lib/python3.5/site-packages/flask/app.py", line 1820, in handle_user_exception
    reraise(exc_type, exc_value, tb)
  File "/mnt/c/Users/hp/Documents/flask_learning/microblog/venv/lib/python3.5/site-packages/flask/_compat.py", line 39, in reraise
    raise value
  File "/mnt/c/Users/hp/Documents/flask_learning/microblog/venv/lib/python3.5/site-packages/flask/app.py", line 1949, in full_dispatch_request
    rv = self.dispatch_request()
  File "/mnt/c/Users/hp/Documents/flask_learning/microblog/venv/lib/python3.5/site-packages/flask/app.py", line 1935, in dispatch_request
    return self.view_functions[rule.endpoint](**req.view_args)
  File "/mnt/c/Users/hp/Documents/flask_learning/microblog/venv/lib/python3.5/site-packages/flask_login/utils.py", line 272, in decorated_view
    return func(*args, **kwargs)
  File "/mnt/c/Users/hp/Documents/flask_learning/microblog/app/routes.py", line 83, in user
    return render_template('user.html', user=user, posts=posts)
  File "/mnt/c/Users/hp/Documents/flask_learning/microblog/venv/lib/python3.5/site-packages/flask/templating.py", line 140, in render_template
    ctx.app,
  File "/mnt/c/Users/hp/Documents/flask_learning/microblog/venv/lib/python3.5/site-packages/flask/templating.py", line 120, in _render
    rv = template.render(context)
  File "/mnt/c/Users/hp/Documents/flask_learning/microblog/venv/lib/python3.5/site-packages/jinja2/environment.py", line 1090, in render
    self.environment.handle_exception()
  File "/mnt/c/Users/hp/Documents/flask_learning/microblog/venv/lib/python3.5/site-packages/jinja2/environment.py", line 832, in handle_exception
    reraise(*rewrite_traceback_stack(source=source))
  File "/mnt/c/Users/hp/Documents/flask_learning/microblog/venv/lib/python3.5/site-packages/jinja2/_compat.py", line 28, in reraise
    raise value.with_traceback(tb)
  File "/mnt/c/Users/hp/Documents/flask_learning/microblog/app/templates/user.html", line 1, in top-level template code
    {% extends "base.html" %}
  File "/mnt/c/Users/hp/Documents/flask_learning/microblog/app/templates/base.html", line 30, in top-level template code
    {% block app_content %}{% endblock %}
  File "/mnt/c/Users/hp/Documents/flask_learning/microblog/app/templates/user.html", line 13, in block "app_content"
    {% elif not current_user.if_following(user) %}
jinja2.exceptions.UndefinedError: 'app.models.User object' has no attribute 'if_following'
