2020-04-11 16:10:00,120 ERROR: Exception on /user/Lilacs [GET] [in /mnt/c/Users/hp/Documents/flask_learning/microblog/venv/lib/python3.5/site-packages/flask/app.py:1891]
Traceback (most recent call last):
  File "/mnt/c/Users/hp/Documents/flask_learning/microblog/venv/lib/python3.5/site-packages/flask/app.py", line 2446, in wsgi_app
    response = self.full_dispatch_request()
  File "/mnt/c/Users/hp/Documents/flask_learning/microblog/venv/lib/python3.5/site-packages/flask/app.py", line 1951, in full_dispatch_request
    rv = self.handle_user_exception(e)
  File "/mnt/c/Users/hp/Documents/flask_learning/microblog/venv/lib/python3.5/site-packages/flask/app.py", line 1820, in handle_user_exception
    reraise(exc_type, exc_value, tb)
  File "/mnt/c/Users/hp/Documents/flask_learning/microblog/venv/lib/python3.5/site-packages/flask/_compat.py", line 39, in reraise
    raise value
  File "/mnt/c/Users/hp/Documents/flask_learning/microblog/venv/lib/python3.5/site-packages/flask/app.py", line 1949, in full_dispatch_request
    rv = self.dispatch_request()
  File "/mnt/c/Users/hp/Documents/flask_learning/microblog/venv/lib/python3.5/site-packages/flask/app.py", line 1935, in dispatch_request
    return self.view_functions[rule.endpoint](**req.view_args)
  File "/mnt/c/Users/hp/Documents/flask_learning/microblog/venv/lib/python3.5/site-packages/flask_login/utils.py", line 272, in decorated_view
    return func(*args, **kwargs)
  File "/mnt/c/Users/hp/Documents/flask_learning/microblog/app/routes.py", line 83, in user
    return render_template('user.html', user=user, posts=posts)
  File "/mnt/c/Users/hp/Documents/flask_learning/microblog/venv/lib/python3.5/site-packages/flask/templating.py", line 140, in render_template
    ctx.app,
  File "/mnt/c/Users/hp/Documents/flask_learning/microblog/venv/lib/python3.5/site-packages/flask/templating.py", line 120, in _render
    rv = template.render(context)
  File "/mnt/c/Users/hp/Documents/flask_learning/microblog/venv/lib/python3.5/site-packages/jinja2/environment.py", line 1090, in render
    self.environment.handle_exception()
  File "/mnt/c/Users/hp/Documents/flask_learning/microblog/venv/lib/python3.5/site-packages/jinja2/environment.py", line 832, in handle_exception
    reraise(*rewrite_traceback_stack(source=source))
  File "/mnt/c/Users/hp/Documents/flask_learning/microblog/venv/lib/python3.5/site-packages/jinja2/_compat.py", line 28, in reraise
    raise value.with_traceback(tb)
  File "/mnt/c/Users/hp/Documents/flask_learning/microblog/app/templates/user.html", line 1, in top-level template code
    {% extends "base.html" %}
  File "/mnt/c/Users/hp/Documents/flask_learning/microblog/app/templates/base.html", line 30, in top-level template code
    {% block content %}{% endblock %}
  File "/mnt/c/Users/hp/Documents/flask_learning/microblog/app/templates/user.html", line 13, in block "content"
    {% elif not current_user.if_following(user) %}
jinja2.exceptions.UndefinedError: 'app.models.User object' has no attribute 'if_following'
